2023-08-13 15:17:13,030 | INFO    | 25019 | Started server process [25019] | server.py:84 
2023-08-13 15:17:13,030 | INFO    | 25019 | Waiting for application startup. | on.py:45 
2023-08-13 15:17:13,065 | ERROR   | 25019 | Traceback (most recent call last):
  File "/Users/chengshuang/Applications/miniconda3/envs/fastapi/lib/python3.10/site-packages/tortoise/__init__.py", line 353, in _discover_models
    module = importlib.import_module(models_path)
  File "/Users/chengshuang/Applications/miniconda3/envs/fastapi/lib/python3.10/importlib/__init__.py", line 126, in import_module
    return _bootstrap._gcd_import(name[level:], package, level)
  File "<frozen importlib._bootstrap>", line 1050, in _gcd_import
  File "<frozen importlib._bootstrap>", line 1027, in _find_and_load
  File "<frozen importlib._bootstrap>", line 992, in _find_and_load_unlocked
  File "<frozen importlib._bootstrap>", line 241, in _call_with_frames_removed
  File "<frozen importlib._bootstrap>", line 1050, in _gcd_import
  File "<frozen importlib._bootstrap>", line 1027, in _find_and_load
  File "<frozen importlib._bootstrap>", line 992, in _find_and_load_unlocked
  File "<frozen importlib._bootstrap>", line 241, in _call_with_frames_removed
  File "<frozen importlib._bootstrap>", line 1050, in _gcd_import
  File "<frozen importlib._bootstrap>", line 1027, in _find_and_load
  File "<frozen importlib._bootstrap>", line 1004, in _find_and_load_unlocked
ModuleNotFoundError: No module named 'apps'

During handling of the above exception, another exception occurred:

Traceback (most recent call last):
  File "/Users/chengshuang/Applications/miniconda3/envs/fastapi/lib/python3.10/site-packages/starlette/routing.py", line 677, in lifespan
    async with self.lifespan_context(app) as maybe_state:
  File "/Users/chengshuang/Applications/miniconda3/envs/fastapi/lib/python3.10/site-packages/starlette/routing.py", line 566, in __aenter__
    await self._router.startup()
  File "/Users/chengshuang/Applications/miniconda3/envs/fastapi/lib/python3.10/site-packages/starlette/routing.py", line 654, in startup
    await handler()
  File "/Users/chengshuang/Applications/miniconda3/envs/fastapi/lib/python3.10/site-packages/tortoise/contrib/fastapi/__init__.py", line 93, in init_orm
    await Tortoise.init(config=config, config_file=config_file, db_url=db_url, modules=modules)
  File "/Users/chengshuang/Applications/miniconda3/envs/fastapi/lib/python3.10/site-packages/tortoise/__init__.py", line 578, in init
    cls._init_apps(apps_config)
  File "/Users/chengshuang/Applications/miniconda3/envs/fastapi/lib/python3.10/site-packages/tortoise/__init__.py", line 414, in _init_apps
    cls.init_models(info["models"], name, _init_relations=False)
  File "/Users/chengshuang/Applications/miniconda3/envs/fastapi/lib/python3.10/site-packages/tortoise/__init__.py", line 395, in init_models
    app_models += cls._discover_models(models_path, app_label)
  File "/Users/chengshuang/Applications/miniconda3/envs/fastapi/lib/python3.10/site-packages/tortoise/__init__.py", line 355, in _discover_models
    raise ConfigurationError(f'Module "{models_path}" not found')
tortoise.exceptions.ConfigurationError: Module "apps.auth.models" not found
 | on.py:119
2023-08-13 15:17:13,065 | ERROR   | 25019 | Application startup failed. Exiting. | on.py:56 
2023-08-13 15:17:26,659 | INFO    | 25048 | Started server process [25048] | server.py:84 
2023-08-13 15:17:26,659 | INFO    | 25048 | Waiting for application startup. | on.py:45 
2023-08-13 15:17:26,663 | ERROR   | 25048 | Traceback (most recent call last):
  File "/Users/chengshuang/Applications/miniconda3/envs/fastapi/lib/python3.10/site-packages/tortoise/__init__.py", line 353, in _discover_models
    module = importlib.import_module(models_path)
  File "/Users/chengshuang/Applications/miniconda3/envs/fastapi/lib/python3.10/importlib/__init__.py", line 126, in import_module
    return _bootstrap._gcd_import(name[level:], package, level)
  File "<frozen importlib._bootstrap>", line 1050, in _gcd_import
  File "<frozen importlib._bootstrap>", line 1027, in _find_and_load
  File "<frozen importlib._bootstrap>", line 992, in _find_and_load_unlocked
  File "<frozen importlib._bootstrap>", line 241, in _call_with_frames_removed
  File "<frozen importlib._bootstrap>", line 1050, in _gcd_import
  File "<frozen importlib._bootstrap>", line 1027, in _find_and_load
  File "<frozen importlib._bootstrap>", line 992, in _find_and_load_unlocked
  File "<frozen importlib._bootstrap>", line 241, in _call_with_frames_removed
  File "<frozen importlib._bootstrap>", line 1050, in _gcd_import
  File "<frozen importlib._bootstrap>", line 1027, in _find_and_load
  File "<frozen importlib._bootstrap>", line 1004, in _find_and_load_unlocked
ModuleNotFoundError: No module named 'apps'

During handling of the above exception, another exception occurred:

Traceback (most recent call last):
  File "/Users/chengshuang/Applications/miniconda3/envs/fastapi/lib/python3.10/site-packages/starlette/routing.py", line 677, in lifespan
    async with self.lifespan_context(app) as maybe_state:
  File "/Users/chengshuang/Applications/miniconda3/envs/fastapi/lib/python3.10/site-packages/starlette/routing.py", line 566, in __aenter__
    await self._router.startup()
  File "/Users/chengshuang/Applications/miniconda3/envs/fastapi/lib/python3.10/site-packages/starlette/routing.py", line 654, in startup
    await handler()
  File "/Users/chengshuang/Applications/miniconda3/envs/fastapi/lib/python3.10/site-packages/tortoise/contrib/fastapi/__init__.py", line 93, in init_orm
    await Tortoise.init(config=config, config_file=config_file, db_url=db_url, modules=modules)
  File "/Users/chengshuang/Applications/miniconda3/envs/fastapi/lib/python3.10/site-packages/tortoise/__init__.py", line 578, in init
    cls._init_apps(apps_config)
  File "/Users/chengshuang/Applications/miniconda3/envs/fastapi/lib/python3.10/site-packages/tortoise/__init__.py", line 414, in _init_apps
    cls.init_models(info["models"], name, _init_relations=False)
  File "/Users/chengshuang/Applications/miniconda3/envs/fastapi/lib/python3.10/site-packages/tortoise/__init__.py", line 395, in init_models
    app_models += cls._discover_models(models_path, app_label)
  File "/Users/chengshuang/Applications/miniconda3/envs/fastapi/lib/python3.10/site-packages/tortoise/__init__.py", line 355, in _discover_models
    raise ConfigurationError(f'Module "{models_path}" not found')
tortoise.exceptions.ConfigurationError: Module "apps.auth.models" not found
 | on.py:119
2023-08-13 15:17:26,663 | ERROR   | 25048 | Application startup failed. Exiting. | on.py:56 
